Workbook

Sheet Revisions
A1: Item | B1: Description of Revision | C1: Date Modified | D1: Comments | E1: Editor(s)
A2: 1 | B2: Document created | C2: 5/3/2021 - 8/23/2021 | E2: JM/CL
A3: 2 | B3: Added IH Machines to Cam line | C3: 44469 | D3: Will start testing week of 10/4/21 | E3: JM
A4: 3 | B4: Changed the fluid type from WSW-87 to PCW-553 on Conrod OP110 | D4: Received notice from Chick of PCR on 10/18/21 | E4: JM
A5: 4 | B5: Moved washers to separate data sheet, and created washer report. | C5: 10/25/2021 - 10/29/2021 | E5: JM/CL
A6: 5 | B6: Hid Lab Data column on Weekly Tab | C6: 44497 | E6: CL
A7: 6 | B7: Added Leadec tabs and formulas on the charts to populate when systems are cleaned | C7: 44509 | E7: JM
A8: 7 | B8: Updated concentration for Cam op 60s to 7-9%. | C8: 44518 | E8: CL
A9: 8 | B9: Added the 1st and 2nd shift Bug-pH Data tabs and linked data to the weekly report tab | C9: 44582 | E9: JM
A10: 9 | B10: Updated the bug-pH data format for Crank Op125 in the washer report tab and linked to the 2nd shift bug-pH data tab | C10: 44582 | E10: JM
A11: 10 | B11: Created IF statements for bug data on Weekly tab to not show zeros when cells are empty on the data tabs | C11: 44620 | E11: JM
A12: 11 | B12: Updated machine number and tank size of Crank Op 120-1/2 | C12: 44685 | E12: JM
A13: 12 | B13: Added Conrod ops 40A/B and 95A/B | C13: 44756 | E13: CL
A14: 13 | B14: Added WR-90 amount to "Washer Data" tab. | C14: 44950 | E14: CL
A15: 14 | B15: Added "2nd Shift" spot check for Mixing Tank. | C15: 44953 | E15: CL
A16: 15 | B16: Swapped/Renamed 1st and 2nd shift Bug-pH Data tabs | C16: 44963 | E16: JM
B19: SPRINT / TRUQ2
A20: 1 | B20: Official issuance for data reporting - all items set at current product and value checks. | C20: 46220

Sheet OP Info
B1: SPRINT - TRUQ2 | Q1: SPRINT - TRUQ2
B2: SHAFT | Q2: SHAFT
B3: Shift # | C3: OP # | D3: Machine # | E3: Sump Size Liters | F3: Product | G3: Conc. Low Limit | H3: Conc. High Limit | I3: Target Conc. | J3: Sump Size Liters | K3: Sump Size Gallons | O3: Tech | Q3: Shift # | S3: Shift # | T3: OP # | U3: Sump Size Liters | V3: Product | W3: Conc. Low Limit | X3: Conc. High Limit | Y3: Target Conc.
B4: MWTH-2 | C4: 10-L1 | D4: TAMCE-00011 | E4: 575 | F4: GTS-120 | G4: 5 | H4: 7 | I4: 6 | J4: =K4*3.785 -> 575 | K4: =E4/3.785 -> 151.91546 | M4: Centering | O4: 1 | Q4: MWTH-2 | S4: MWTH-2 | T4: 10-L1 | U4: 575 | V4: GTS-120 | W4: 5 | X4: 7 | Y4: 6
B5: MWTH-2 | C5: 20-L1 | D5: TAMLA-00050 | E5: 630 | F5: GTS-120 | G5: 5 | H5: 7 | I5: 6 | J5: =K5*3.785 -> 630 | K5: =E5/3.785 -> 166.4465 | M5: Lathe | O5: 2 | Q5: MWTH-2 | S5: MWTH-2 | T5: 20-L1 | U5: 630 | V5: GTS-120 | W5: 5 | X5: 7 | Y5: 6
B6: MWTH-2 | C6: 30-L1 | D6: TAMLA-00053 | E6: 630 | F6: GTS-120 | G6: 5 | H6: 7 | I6: 6 | J6: =K6*3.785 -> 630 | K6: =E6/3.785 -> 166.4465 | M6: Lathe | O6: 1 | Q6: MWTH-2 | S6: MWTH-2 | T6: 30-L1 | U6: 630 | V6: GTS-120 | W6: 5 | X6: 7 | Y6: 6
B7: MWTH-2 | C7: 50 A/B-L1 | D7: TAMIH-00017 / TAMIH-00018 | E7: 3300 | F7: AQ-YB | G7: 5 | H7: 7 | I7: 6 | J7: =K7*3.785 -> 3300 | K7: =E7/3.785 -> 871.86262 | M7: Induction Hardening | O7: 1 | Q7: MWTH-2 | S7: MWTH-2 | T7: 50 A/B-L1 | U7: 3300 | V7: AQ-YB | W7: 5 | X7: 7 | Y7: 6
B8: MWTH-2 | C8: 70-L1 | D8: TAMLA-00051 | E8: 630 | F8: GTS-120 | G8: 5 | H8: 7 | I8: 6 | J8: =K8*3.785 -> 630 | K8: =E8/3.785 -> 166.4465 | M8: Lathe | O8: 1 | Q8: MWTH-2 | S8: MWTH-2 | T8: 70-L1 | U8: 630 | V8: GTS-120 | W8: 5 | X8: 7 | Y8: 6
B9: MWTH-2 | C9: 80-L1 | D9: TAMLA-00052 | E9: 630 | F9: GTS-120 | G9: 5 | H9: 7 | I9: 6 | J9: =K9*3.785 -> 630 | K9: =E9/3.785 -> 166.4465 | M9: Lathe | O9: 2 | Q9: MWTH-2 | S9: MWTH-2 | T9: 80-L1 | U9: 630 | V9: GTS-120 | W9: 5 | X9: 7 | Y9: 6
B10: MWTH-2 | C10: 90-L1 | D10: TAMGR-00113 | E10: 690 | F10: GTS-120 | G10: 5 | H10: 7 | I10: 6 | J10: =K10*3.785 -> 690 | K10: =E10/3.785 -> 182.29855 | M10: Grinding | O10: 1 | Q10: MWTH-2 | S10: MWTH-2 | T10: 90-L1 | U10: 690 | V10: GTS-120 | W10: 5 | X10: 7 | Y10: 6
B11: MWTH-2 | C11: 100A-L1 | D11: NAMSP-00282 | E11: 850 | F11: GTS-120 | G11: 7 | H11: 9 | I11: 8 | J11: =K11*3.785 -> 850 | K11: =E11/3.785 -> 224.57067 | M11: Drilling | O11: 2 | Q11: MWTH-2 | S11: MWTH-2 | T11: 100A-L1 | U11: 850 | V11: GTS-120 | W11: 7 | X11: 9 | Y11: 8
B12: MWTH-2 | C12: 100B-L1 | D12: NAMSP-00284 | E12: 850 | F12: GTS-120 | G12: 7 | H12: 9 | I12: 8 | J12: =K12*3.785 -> 850 | K12: =E12/3.785 -> 224.57067 | M12: Drilling | O12: 1 | Q12: MWTH-2 | S12: MWTH-2 | T12: 100B-L1 | U12: 850 | V12: GTS-120 | W12: 7 | X12: 9 | Y12: 8
B13: TF-2 | C13: 10-L2 | D13: TAMCE-00010 | E13: 575 | F13: GTS-120 | G13: 5 | H13: 7 | I13: 6 | J13: =K13*3.785 -> 575 | K13: =E13/3.785 -> 151.91546 | M13: Centering | O13: 2 | Q13: TF-2 | S13: MWTH-2 | T13: 10-L3 | U13: 575 | V13: GTS-120 | W13: 5 | X13: 7 | Y13: 6
B14: TF-2 | C14: 20-L2 | D14: TAMLA-00048 | E14: 685 | F14: GTS-120 | G14: 5 | H14: 7 | I14: 6 | J14: =K14*3.785 -> 685 | K14: =E14/3.785 -> 180.97754 | M14: Lathe | O14: 1 | Q14: TF-2 | S14: MWTH-2 | T14: 20-L3 | U14: 630 | V14: GTS-120 | W14: 5 | X14: 7 | Y14: 6
B15: TF-2 | C15: 30-L2 | D15: TAMLA-00046 | E15: 685 | F15: GTS-120 | G15: 5 | H15: 7 | I15: 6 | J15: =K15*3.785 -> 685 | K15: =E15/3.785 -> 180.97754 | M15: Lathe | O15: 2 | Q15: TF-2 | S15: MWTH-2 | T15: 30-L3 | U15: 630 | V15: GTS-120 | W15: 5 | X15: 7 | Y15: 6
... B29: TF-2 | C29: 100A-L3 | D29: NAMSP-00341 | E29: 850 | F29: MDS-570 | G29: 7 | H29: 9 | I29: 8 | J29: =K29*3.785 -> 850 | K29: =E29/3.785 -> 224.57067 | M29: Drilling | O29: 1 | Q29: TF-2 | S29: MWTH-1 | T29: 100B-L5 | U29: 850 | V29: GTS-120 | W29: 7 | X29: 9 | Y29: 8
B30: TF-2 | C30: 100B-L3 | D30: NAMSP-00343 | E30: 850 | F30: MDS-570 | G30: 7 | H30: 9 | I30: 8 | J30: =K30*3.785 -> 850 | K30: =E30/3.785 -> 224.57067 | M30: Drilling | O30: 2 | Q30: TF-2
B31: MWTH-1 | C31: 10-L4 | D31: TAMCE-00012 | E31: 575 | F31: GTS-120 | G31: 5 | H31: 7 | I31: 6 | J31: =K31*3.785 -> 575 | K31: =E31/3.785 -> 151.91546 | M31: Centering | O31: 1 | Q31: MWTH-1 | S31: TF-2 | T31: 10-L2 | U31: 575 | V31: GTS-120 | W31: 5 | X31: 7 | Y31: 6
B32: MWTH-1 | C32: 20-L4 | D32: TAMLA-00054 | E32: 685 | F32: GTS-120 | G32: 5 | H32: 7 | I32: 6 | J32: =K32*3.785 -> 685 | K32: =E32/3.785 -> 180.97754 | M32: Lathe | O32: 2 | Q32: MWTH-1 | S32: TF-2 | T32: 20-L2 | U32: 685 | V32: GTS-120 | W32: 5 | X32: 7 | Y32: 6
B33: MWTH-1 | C33: 30-L4 | D33: TAMLA-00061 | E33: 685 | F33: GTS-120 | G33: 5 | H33: 7 | I33: 6 | J33: =K33*3.785 -> 685 | K33: =E33/3.785 -> 180.97754 | M33: Lathe | O33: 1 | Q33: MWTH-1 | S33: TF-2 | T33: 30-L2 | U33: 685 | V33: GTS-120 | W33: 5 | X33: 7 | Y33: 6
B34: MWTH-1 | C34: 50 A/B-L4 | D34: TAMIH-00023 / TAMIH-00024 | E34: 3300 | F34: AQ-YB | G34: 5 | H34: 7 | I34: 6 | J34: =K34*3.785 -> 3300 | K34: =E34/3.785 -> 871.86262 | M34: Induction Hardening | O34: 2 | Q34: MWTH-1 | S34: TF-2 | T34: 50 A/B-L2 | U34: 3300 | V34: AQ-YB | W34: 5 | X34: 7 | Y34: 6
B35: TF-1 | C35: 70-L4 | D35: TAMLA-00062 | E35: 630 | F35: GTS-120 | G35: 5 | H35: 7 | I35: 6 | J35: =K35*3.785 -> 630 | K35: =E35/3.785 -> 166.4465 | M35: Lathe | O35: 2 | Q35: TF-1 | S35: TF-2 | T35: 70-L2 | U35: 630 | V35: GTS-120 | W35: 5 | X35: 7 | Y35: 6
B36: TF-1 | C36: 80-L4 | D36: TAMLA-00063 | E36: 630 | F36: GTS-120 | G36: 5 | H36: 7 | I36: 6 | J36: =K36*3.785 -> 630 | K36: =E36/3.785 -> 166.4465 | M36: Lathe | O36: 1 | Q36: TF-1 | S36: TF-2 | T36: 80-L2 | U36: 630 | V36: GTS-120 | W36: 5 | X36: 7 | Y36: 6
B37: TF-1 | C37: 90-L4 | D37: TAMGR-00114 | E37: 690 | F37: GTS-120 | G37: 5 | H37: 7 | I37: 6 | J37: =K37*3.785 -> 690 | K37: =E37/3.785 -> 182.29855 | M37: Grinding | O37: 2 | Q37: TF-1 | S37: TF-2 | T37: 90-L2 | U37: 690 | V37: GTS-120 | W37: 5 | X37: 7 | Y37: 6
B38: TF-1 | C38: 100A-L4 | D38: NAMSP-00306 | E38: 850 | F38: MDS-570 | G38: 7 | H38: 9 | I38: 8 | J38: =K38*3.785 -> 850 | K38: =E38/3.785 -> 224.57067 | M38: Drilling | O38: 1 | Q38: TF-1 | S38: TF-2 | T38: 100A-L2 | U38: 850 | V38: GTS-120 | W38: 7 | X38: 9 | Y38: 8
B39: TF-1 | C39: 100B-L4 | D39: NAMSP-00327 | E39: 850 | F39: MDS-570 | G39: 7 | H39: 9 | I39: 8 | J39: =K39*3.785 -> 850 | K39: =E39/3.785 -> 224.57067 | M39: Drilling | O39: 2 | Q39: TF-1 | S39: TF-2 | T39: 100B-L2 | U39: 850 | V39: GTS-120 | W39: 7 | X39: 9 | Y39: 8
B40: MWTH-1 | C40: 10-L5 | D40: TAMCE-00014 | E40: 575 | F40: GTS-120 | G40: 5 | H40: 7 | I40: 6 | J40: =K40*3.785 -> 575 | K40: =E40/3.785 -> 151.91546 | M40: Centering | O40: 1 | Q40: MWTH-1 | S40: TF-2 | T40: 70-L3 | U40: 630 | V40: GTS-120 | W40: 5 | X40: 7 | Y40: 6
B41: MWTH-1 | C41: 20-L5 | D41: TAMLA-00068 | E41: 630 | F41: GTS-120 | G41: 5 | H41: 7 | I41: 6 | J41: =K41*3.785 -> 630 | K41: =E41/3.785 -> 166.4465 | M41: Lathe | O41: 2 | Q41: MWTH-1 | S41: TF-2 | T41: 80-L3 | U41: 630 | V41: GTS-120 | W41: 5 | X41: 7 | Y41: 6
B42: MWTH-1 | C42: 30-L5 | D42: TAMLA-00069 | E42: 630 | F42: GTS-120 | G42: 5 | H42: 7 | I42: 6 | J42: =K42*3.785 -> 630 | K42: =E42/3.785 -> 166.4465 | M42: Lathe | O42: 1 | Q42: MWTH-1 | S42: TF-2 | T42: 90-L3 | U42: 690 | V42: GTS-120 | W42: 5 | X42: 7 | Y42: 6
... B58: TF-1 | C58: 100B-L6 | D58: NAMSP-00280 | E58: 850 | F58: GTS-120 | G58: 7 | H58: 9 | I58: 8 | J58: =K58*3.785 -> 850 | K58: =E58/3.785 -> 224.57067 | M58: Drilling | O58: 2 | Q58: TF-1 | S58: TF-1 | T58: 100A-L6 | U58: 850 | V58: GTS-120 | W58: 7 | X58: 9 | Y58: 8
S59: TF-1 | T59: 100B-L6 | U59: 850 | V59: GTS-120 | W59: 7 | X59: 9 | Y59: 8
B60: MWTH-2 | C60: SHAWB-58 | D60: TAMWB-00058 | E60: 925 | F60: G-5300ME | G60: 0.015 | H60: 0.025 | I60: 0.02 | J60: =E60 -> 925 | K60: =E60/3.785 -> 244.38573 | Q60: MWTH-2
B61: MWTH-2 | C61: SHAWB-60 | D61: TAMWB-00060 | E61: 925 | F61: G-5300ME | G61: 0.015 | H61: 0.025 | I61: 0.02 | J61: =E61 -> 925 | K61: =E61/3.785 -> 244.38573 | Q61: MWTH-2
B62: MWTH-1 | C62: SHAWB-59 | D62: TAMWB-00059 | E62: 925 | F62: G-5300ME | G62: 0.015 | H62: 0.025 | I62: 0.02 | J62: =E62 -> 925 | K62: =E62/3.785 -> 244.38573 | Q62: MWTH-1
B65: CARRIER | Q65: CARRIER
B66: Shift # | C66: OP # | D66: Machine # | E66: Sump Size Liters | F66: Product | G66: Conc. Low Limit | H66: Conc. High Limit | I66: Target Conc. | J66: Sump Size Liters | K66: Sump Size Gallons | Q66: Shift # | S66: Shift # | T66: OP # | U66: Sump Size Liters | V66: Product | W66: Conc. Low Limit | X66: Conc. High Limit | Y66: Target Conc.
B67: MWTH-1 | C67: 10A | D67: TAMTV-00004 | E67: 590 | F67: GTS-120 | G67: 5 | H67: 7 | I67: 6 | J67: =K67*3.785 -> 590 | K67: =E67/3.785 -> 155.87847 | Q67: MWTH-1 | S67: MWTH-1 | T67: 10A | U67: 590 | V67: GTS-120 | W67: 5 | X67: 7 | Y67: 6
B68: MWTH-1 | C68: 20A | D68: TAMMM-00024 | E68: 875 | F68: GTS-120 | G68: 5 | H68: 7 | I68: 6 | J68: =K68*3.785 -> 875 | K68: =E68/3.785 -> 231.17569 | Q68: MWTH-1 | S68: MWTH-1 | T68: 20A | U68: 875 | V68: GTS-120 | W68: 5 | X68: 7 | Y68: 6
B69: TF-1 | C69: 40A | D69: TAMMM-00030 | E69: 875 | F69: GTS-120 | G69: 5 | H69: 7 | I69: 6 | J69: =K69*3.785 -> 875 | K69: =E69/3.785 -> 231.17569 | Q69: TF-1 | S69: MWTH-1 | T69: 10B | U69: 590 | V69: GTS-120 | W69: 5 | X69: 7 | Y69: 6
B70: TF-1 | C70: 50A | D70: TAMMM-00025 | E70: 875 | F70: GTS-120 | G70: 5 | H70: 7 | I70: 6 | J70: =K70*3.785 -> 875 | K70: =E70/3.785 -> 231.17569 | Q70: TF-1 | S70: MWTH-1 | T70: 20B | U70: 875 | V70: GTS-120 | W70: 5 | X70: 7 | Y70: 6
...

Sheet MWTh
B1: Shift: | G1: Tech: | M1: WEEK: | N1: Shift: | S1: Tech: | Y1: WEEK: | Z1: Shift: | AA1: 2nd | AE1: Tech: | AK1: WEEK: | AL1: Shift: | AM1: 2nd | AQ1: Tech: | AW1: WEEK: | AX1: Shift: | AY1: 2nd | BC1: Tech: | BI1: WEEK: | BK1: WEEKLY COMMENTS | BL1: Shift: | BM1: 2nd | BQ1: Tech: | BW1: WEEK: | BX1: Shift: | BY1: 2nd | CC1: Tech: | CI1: WEEK: | CJ1: Shift: | CK1: 2nd | CO1: Tech: | CU1: WEEK: | CV1: Shift: | CW1: 2nd | DA1: Tech: | DG1: WEEK: | DH1: Shift: | DI1: 2nd | DM1: Tech: | DS1: WEEK: | DU1: WEEKLY COMMENTS | DV1: Shift: | DW1: 2nd | EA1: Tech: | EG1: WEEK: | EH1: Shift: | EI1: 2nd | EM1: Tech: | ES1: WEEK: | ET1: Shift: | EU1: 2nd | EY1: Tech: | FE1: WEEK: | FF1: Shift: | FG1: 2nd | FK1: Tech: | FQ1: WEEK: | FR1: Shift: | FS1: 2nd | FW1: Tech: | GC1: WEEK: | GE1: WEEKLY COMMENTS | GF1: Shift: | GG1: 2nd | GK1: Tech: | GQ1: WEEK: | GR1: Shift: | GS1: 2nd | GW1: Tech: | HC1: WEEK: | HD1: Shift: | HE1: 2nd | HI1: Tech: | HO1: WEEK: | HP1: Shift: | HQ1: 2nd | HU1: Tech: | IA1: WEEK: | IB1: Shift: | IC1: 2nd | IG1: Tech: | IM1: WEEK: | IO1: WEEKLY COMMENTS | IP1: Shift: | IQ1: 2nd | IU1: Tech: | JA1: WEEK: | JB1: Shift: | JC1: 2nd | JG1: Tech: | JM1: WEEK: | JN1: Shift: | JO1: 2nd | JS1: Tech: | JY1: WEEK: | JZ1: Shift: | KA1: 2nd | KE1: Tech: | KK1: WEEK: | KL1: Shift: | KM1: 2nd | KQ1: Tech: | KW1: WEEK: | KY1: WEEKLY COMMENTS
B2: Type: | C2: Spot Checks | G2: Date: | H2: 46300 | M2: 1 | N2: Type: | O2: Spot Checks | S2: Date: | T2: =H2+1 -> 46301 | Y2: 1 | Z2: Type: | AA2: Spot Checks | AE2: Date: | AF2: =T2+1 -> 46302 | AK2: 1 | AL2: Type: | AM2: Spot Checks | AQ2: Date: | AR2: =AF2+1 -> 46303 | AW2: 1 | AX2: Type: | AY2: Spot Checks | BC2: Date: | BD2: =AR2+1 -> 46304 | BI2: 1 | BL2: Type: | BM2: Spot Checks | BQ2: Date: | BR2: =BD2+3 -> 46307 | BW2: 2 | BX2: Type: | BY2: Spot Checks | CC2: Date: | CD2: =BR2+1 -> 46308 | CI2: 2 | CJ2: Type: | CK2: Spot Checks | CO2: Date: | CP2: =CD2+1 -> 46309 | CU2: 2 | CV2: Type: | CW2: Spot Checks | DA2: Date: | DB2: =CP2+1 -> 46310 | DG2: 2 | DH2: Type: | DI2: Spot Checks | DM2: Date: | DN2: =DB2+1 -> 46311 | DS2: 2 | DV2: Type: | DW2: Spot Checks | EA2: Date: | EB2: =DN2+3 -> 46314 | EG2: 3 | EH2: Type: | EI2: Spot Checks | EM2: Date: | EN2: =EB2+1 -> 46315 | ES2: 3 | ET2: Type: | EU2: Spot Checks | EY2: Date: | EZ2: =EN2+1 -> 46316 | FE2: 3 | FF2: Type: | FG2: Spot Checks | FK2: Date: | FL2: =EZ2+1 -> 46317 | FQ2: 3 | FR2: Type: | FS2: Spot Checks | FW2: Date: | FX2: =FL2+1 -> 46318 | GC2: 3 | GF2: Type: | GG2: Spot Checks | GK2: Date: | GL2: =FX2+3 -> 46321 | GQ2: 4 | GR2: Type: | GS2: Spot Checks | GW2: Date: | GX2: =GL2+1 -> 46322 | HC2: 4 | HD2: Type: | HE2: Spot Checks | HI2: Date: | HJ2: =GX2+1 -> 46323 | HO2: 4 | HP2: Type: | HQ2: Spot Checks | HU2: Date: | HV2: =HJ2+1 -> 46324 | IA2: 4 | IB2: Type: | IC2: Spot Checks | IG2: Date: | IH2: =HV2+1 -> 46325 | IM2: 4 | IP2: Type: | IQ2: Spot Checks | IU2: Date: | IV2: =IH2+3 -> 46328 | JA2: 5 | JB2: Type: | JC2: Spot Checks | JG2: Date: | JH2: =IV2+1 -> 46329 | JM2: 5 | JN2: Type: | JO2: Spot Checks | JS2: Date: | JT2: =JH2+1 -> 46330 | JY2: 5 | JZ2: Type: | KA2: Spot Checks | KE2: Date: | KF2: =JT2+1 -> 46331 | KK2: 5 | KL2: Type: | KM2: Spot Checks | KQ2: Date: | KR2: =KF2+1 -> 46332 | KW2: 5
B4: SHAFT | M4: =H2 -> 46300 | N4: SHAFT | Y4: =T2 -> 46301 | Z4: SHAFT | AK4: =AF2 -> 46302 | AL4: SHAFT | AW4: =AR2 -> 46303 | AX4: SHAFT | BI4: =BD2 -> 46304 | BJ4: TOTAL VIRGIN | BK4: WEEKLY COMMENTS | BL4: SHAFT | BW4: =BR2 -> 46307 | BX4: SHAFT | CI4: =CD2 -> 46308 | CJ4: SHAFT | CU4: =CP2 -> 46309 | CV4: SHAFT | DG4: =DB2 -> 46310 | DH4: SHAFT | DS4: =DN2 -> 46311 | DT4: TOTAL VIRGIN | DU4: WEEKLY COMMENTS | DV4: SHAFT | EG4: =EB2 -> 46314 | EH4: SHAFT | ES4: =EN2 -> 46315 | ET4: SHAFT | FE4: =EZ2 -> 46316 | FF4: SHAFT | FQ4: =FL2 -> 46317 | FR4: SHAFT | GC4: =FX2 -> 46318 | GD4: TOTAL VIRGIN | GE4: WEEKLY COMMENTS | GF4: SHAFT | GQ4: =GL2 -> 46321 | GR4: SHAFT | HC4: =GX2 -> 46322 | HD4: SHAFT | HO4: =HJ2 -> 46323 | HP4: SHAFT | IA4: =HV2 -> 46324 | IB4: SHAFT | IM4: =IH2 -> 46325 | IN4: TOTAL VIRGIN | IO4: WEEKLY COMMENTS | IP4: SHAFT | JA4: =IV2 -> 46328 | JB4: SHAFT | JM4: =JH2 -> 46329 | JN4: SHAFT | JY4: =JT2 -> 46330 | JZ4: SHAFT | KK4: =KF2 -> 46331 | KL4: SHAFT | KW4: =KR2 -> 46332 | KX4: TOTAL VIRGIN | KY4: WEEKLY COMMENTS
B5: OP # | C5: Product | D5: Sump Size (Liters) | E5: Conc. Range (%) | F5: Initial Refrac | G5: Initial RI | H5: Tank Level | I5: Skimmer | J5: Product Added (Liters) | K5: Product Added (Gal.) | L5: Comments | M5: Final RI | N5: OP # | O5: Product | P5: Sump Size (Liters) | Q5: Conc. Range (%) | R5: Initial Refrac | S5: Initial RI | T5: Tank Level | U5: Skimmer | V5: Product Added (Liters) | W5: Product Added (Gal.) | X5: Comments | Y5: Final RI | Z5: OP # | AA5: Product | AB5: Sump Size (Liters) | AC5: Conc. Range (%) | AD5: Initial Refrac | AE5: Initial RI | AF5: Tank Level | AG5: Skimmer | AH5: Product Added (Liters) | AI5: Product Added (Gal.) | AJ5: Comments | AK5: Final RI | AL5: OP # | AM5: Product | AN5: Sump Size (Liters) | AO5: Conc. Range (%) | AP5: Initial Refrac | AQ5: Initial RI | AR5: Tank Level | AS5: Skimmer | AT5: Product Added (Liters) | AU5: Product Added (Gal.) | AV5: Comments | AW5: Final RI | AX5: OP # | AY5: Product | AZ5: Sump Size (Liters) | BA5: Conc. Range (%) | BB5: Initial Refrac | BC5: Initial RI | BD5: Tank Level | BE5: Skimmer | BF5: Product Added (Liters) | BG5: Product Added (Gal.) | BH5: Comments | BI5: Final RI | BL5: OP # | BM5: Product | BN5: Sump Size (Liters) | BO5: Conc. Range (%) | BP5: Initial Refrac | BQ5: Initial RI | BR5: Tank Level | BS5: Skimmer | BT5: Product Added (Liters) | BU5: Product Added (Gal.) | BV5: Comments | BW5: Final RI | BX5: OP # | BY5: Product | BZ5: Sump Size (Liters) | CA5: Conc. Range (%) | CB5: Initial Refrac | CC5: Initial RI | CD5: Tank Level | CE5: Skimmer | CF5: Product Added (Liters) | CG5: Product Added (Gal.) | CH5: Comments | CI5: Final RI | CJ5: OP # | CK5: Product | CL5: Sump Size (Liters) | CM5: Conc. Range (%) | CN5: Initial Refrac | CO5: Initial RI | CP5: Tank Level | CQ5: Skimmer | CR5: Product Added (Liters) | CS5: Product Added (Gal.) | CT5: Comments | CU5: Final RI | CV5: OP # | CW5: Product | CX5: Sump Size (Liters) | CY5: Conc. Range (%) | CZ5: Initial Refrac | DA5: Initial RI | DB5: Tank Level | DC5: Skimmer | DD5: Product Added (Liters) | DE5: Product Added (Gal.) | DF5: Comments | DG5: Final RI | DH5: OP # | DI5: Product | DJ5: Sump Size (Liters) | DK5: Conc. Range (%) | DL5: Initial Refrac | DM5: Initial RI | DN5: Tank Level | DO5: Skimmer | DP5: Product Added (Liters) | DQ5: Product Added (Gal.) | DR5: Comments | DS5: Final RI | DV5: OP # | DW5: Product | DX5: Sump Size (Liters) | DY5: Conc. Range (%) | DZ5: Initial Refrac | EA5: Initial RI | EB5: Tank Level | EC5: Skimmer | ED5: Product Added (Liters) | EE5: Product Added (Gal.) | EF5: Comments | EG5: Final RI | EH5: OP # | EI5: Product | EJ5: Sump Size (Liters) | EK5: Conc. Range (%) | EL5: Initial Refrac | EM5: Initial RI | EN5: Tank Level | EO5: Skimmer | EP5: Product Added (Liters) | EQ5: Product Added (Gal.) | ER5: Comments | ES5: Final RI | ET5: OP # | EU5: Product | EV5: Sump Size (Liters) | EW5: Conc. Range (%) | EX5: Initial Refrac | EY5: Initial RI | EZ5: Tank Level | FA5: Skimmer | FB5: Product Added (Liters) | FC5: Product Added (Gal.) | FD5: Comments | FE5: Final RI | FF5: OP # | FG5: Product | FH5: Sump Size (Liters) | FI5: Conc. Range (%) | FJ5: Initial Refrac | FK5: Initial RI | FL5: Tank Level | FM5: Skimmer | FN5: Product Added (Liters) | FO5: Product Added (Gal.) | FP5: Comments | FQ5: Final RI | FR5: OP # | FS5: Product | FT5: Sump Size (Liters) | FU5: Conc. Range (%) | FV5: Initial Refrac | FW5: Initial RI | FX5: Tank Level | FY5: Skimmer | FZ5: Product Added (Liters) | GA5: Product Added (Gal.) | GB5: Comments | GC5: Final RI | GF5: OP # | GG5: Product | GH5: Sump Size (Liters) | GI5: Conc. Range (%) | GJ5: Initial Refrac | GK5: Initial RI | GL5: Tank Level | GM5: Skimmer | GN5: Product Added (Liters) | GO5: Product Added (Gal.) | GP5: Comments | GQ5: Final RI | GR5: OP # | GS5: Product | GT5: Sump Size (Liters) | GU5: Conc. Range (%) | GV5: Initial Refrac | GW5: Initial RI | GX5: Tank Level | GY5: Skimmer | GZ5: Product Added (Liters) | HA5: Product Added (Gal.) | HB5: Comments | HC5: Final RI | HD5: OP # | HE5: Product | HF5: Sump Size (Liters) | HG5: Conc. Range (%) | HH5: Initial Refrac | HI5: Initial RI | HJ5: Tank Level | HK5: Skimmer | HL5: Product Added (Liters) | HM5: Product Added (Gal.) | HN5: Comments | HO5: Final RI | HP5: OP # | HQ5: Product | HR5: Sump Size (Liters) | HS5: Conc. Range (%) | HT5: Initial Refrac | HU5: Initial RI | HV5: Tank Level | HW5: Skimmer | HX5: Product Added (Liters) | HY5: Product Added (Gal.) | HZ5: Comments | IA5: Final RI | IB5: OP # | IC5: Product | ID5: Sump Size (Liters) | IE5: Conc. Range (%) | IF5: Initial Refrac | IG5: Initial RI | IH5: Tank Level | II5: Skimmer | IJ5: Product Added (Liters) | IK5: Product Added (Gal.) | IL5: Comments | IM5: Final RI | IP5: OP # | IQ5: Product | IR5: Sump Size (Liters) | IS5: Conc. Range (%) | IT5: Initial Refrac | IU5: Initial RI | IV5: Tank Level | IW5: Skimmer | IX5: Product Added (Liters) | IY5: Product Added (Gal.) | IZ5: Comments | JA5: Final RI | JB5: OP # | JC5: Product | JD5: Sump Size (Liters) | JE5: Conc. Range (%) | JF5: Initial Refrac | JG5: Initial RI | JH5: Tank Level | JI5: Skimmer | JJ5: Product Added (Liters) | JK5: Product Added (Gal.) | JL5: Comments | JM5: Final RI | JN5: OP # | JO5: Product | JP5: Sump Size (Liters) | JQ5: Conc. Range (%) | JR5: Initial Refrac | JS5: Initial RI | JT5: Tank Level | JU5: Skimmer | JV5: Product Added (Liters) | JW5: Product Added (Gal.) | JX5: Comments | JY5: Final RI | JZ5: OP # | KA5: Product | KB5: Sump Size (Liters) | KC5: Conc. Range (%) | KD5: Initial Refrac | KE5: Initial RI | KF5: Tank Level | KG5: Skimmer | KH5: Product Added (Liters) | KI5: Product Added (Gal.) | KJ5: Comments | KK5: Final RI | KL5: OP # | KM5: Product | KN5: Sump Size (Liters) | KO5: Conc. Range (%) | KP5: Initial Refrac | KQ5: Initial RI | KR5: Tank Level | KS5: Skimmer | KT5: Product Added (Liters) | KU5: Product Added (Gal.) | KV5: Comments | KW5: Final RI
A6: MWTH-1 | B6: 10-L1 | C6: =VLOOKUP($B6,'OP Info'!$C$4:$J$62,4,FALSE) -> GTS-120 | D6: =VLOOKUP($B6,'OP Info'!$C$4:$J$62,3,FALSE) -> 575 | E6: =CONCATENATE(VLOOKUP($B6,'OP Info'!$C$4:$J$62,5,FALSE),"%-",VLOOKUP($B6,'OP Info'!$C$4:$J$62,6,FALSE),"%") -> 5%-7% | G6: =F6*VLOOKUP(C6,$B$157:$C$159,2,FALSE) -> 0 | J6: =IF(F6="","",IF(G6>0.049999,"",((6-ROUND(G6*100,1))*0.01)*D6)) | K6: =IF(J6="","",J6*0.264172) | N6: =$B6 -> 10-L1 | O6: =$C6 -> GTS-120 | P6: =$D6 -> 575 | Q6: =$E6 -> 5%-7% | S6: =R6*VLOOKUP(O6,$B$157:$C$159,2,FALSE) -> 0 | V6: =IF(R6="","",IF(S6>0.049999,"",((6-ROUND(S6*100,1))*0.01)*P6)) | W6: =IF(V6="","",V6*0.264172) | Y6: =IF(V6="",IF(S6=0,"",S6),"") | Z6: =$B6 -> 10-L1 | AA6: =$C6 -> GTS-120 | AB6: =$D6 -> 575 | AC6: =$E6 -> 5%-7% | AE6: =AD6*VLOOKUP(AA6,$B$157:$C$159,2,FALSE) -> 0 | AH6: =IF(AD6="","",IF(AE6>0.049999,"",((6-ROUND(AE6*100,1))*0.01)*AB6)) | AI6: =IF(AH6="","",AH6*0.264172) | AK6: =IF(AH6="",IF(AE6=0,"",AE6),"") | AL6: =$B6 -> 10-L1 | AM6: =$C6 -> GTS-120 | AN6: =$D6 -> 575 | AO6: =$E6 -> 5%-7% | AQ6: =AP6*VLOOKUP(AM6,$B$157:$C$159,2,FALSE) -> 0 | AT6: =IF(AP6="","",IF(AQ6>0.049999,"",((6-ROUND(AQ6*100,1))*0.01)*AN6)) | AU6: =IF(AT6="","",AT6*0.264172) | AW6: =IF(AT6="",IF(AQ6=0,"",AQ6),"") | AX6: =$B6 -> 10-L1 | AY6: =$C6 -> GTS-120 | AZ6: =$D6 -> 575 | BA6: =$E6 -> 5%-7% | BC6: =BB6*VLOOKUP(AY6,$B$157:$C$159,2,FALSE) -> 0 | BF6: =IF(BB6="","",IF(BC6>0.049999,"",((6-ROUND(BC6*100,1))*0.01)*AZ6)) | BG6: =IF(BF6="","",BF6*0.264172) | BI6: =IF(BF6="",IF(BC6=0,"",BC6),"") | BJ6: =SUM(K6,W6,AI6,AU6,BG6) -> 0 | BK6: =L6&X6&AJ6&AV6&BH6 | BL6: =$B6 -> 10-L1 | BM6: =$C6 -> GTS-120 | BN6: =$D6 -> 575 | BO6: =$E6 -> 5%-7% | BQ6: =BP6*VLOOKUP(BM6,$B$157:$C$159,2,FALSE) -> 0 | BT6: =IF(BP6="","",IF(BQ6>0.049999,"",((6-ROUND(BQ6*100,1))*0.01)*BN6)) | BU6: =IF(BT6="","",BT6*0.264172) | BW6: =IF(BT6="",IF(BQ6=0,"",BQ6),"") | BX6: =$B6 -> 10-L1 | BY6: =$C6 -> GTS-120 | BZ6: =$D6 -> 575 | CA6: =$E6 -> 5%-7% | CC6: =CB6*VLOOKUP(BY6,$B$157:$C$159,2,FALSE) -> 0 | CF6: =IF(CB6="","",IF(CC6>0.049999,"",((6-ROUND(CC6*100,1))*0.01)*BZ6)) | CG6: =IF(CF6="","",CF6*0.264172) | CI6: =IF(CF6="",IF(CC6=0,"",CC6),"") | CJ6: =$B6 -> 10-L1 | CK6: =$C6 -> GTS-120 | CL6: =$D6 -> 575 | CM6: =$E6 -> 5%-7% | CO6: =CN6*VLOOKUP(CK6,$B$157:$C$159,2,FALSE) -> 0 | CR6: =IF(CN6="","",IF(CO6>0.049999,"",((6-ROUND(CO6*100,1))*0.01)*CL6)) | CS6: =IF(CR6="","",CR6*0.264172) | CU6: =IF(CR6="",IF(CO6=0,"",CO6),"") | CV6: =$B6 -> 10-L1 | CW6: =$C6 -> GTS-120 | CX6: =$D6 -> 575 | CY6: =$E6 -> 5%-7% | DA6: =CZ6*VLOOKUP(CW6,$B$157:$C$159,2,FALSE) -> 0 | DD6: =IF(CZ6="","",IF(DA6>0.049999,"",((6-ROUND(DA6*100,1))*0.01)*CX6)) | DE6: =IF(DD6="","",DD6*0.264172) | DG6: =IF(DD6="",IF(DA6=0,"",DA6),"") | DH6: =$B6 -> 10-L1 | DI6: =$C6 -> GTS-120 | DJ6: =$D6 -> 575 | DK6: =$E6 -> 5%-7% | DM6: =DL6*VLOOKUP(DI6,$B$157:$C$159,2,FALSE) -> 0 | DP6: =IF(DL6="","",IF(DM6>0.049999,"",((6-ROUND(DM6*100,1))*0.01)*DJ6)) | DQ6: =IF(DP6="","",DP6*0.264172) | DS6: =IF(DP6="",IF(DM6=0,"",DM6),"") | DT6: =SUM(BU6,CG6,CS6,DE6,DQ6) -> 0 | DU6: =BV6&CH6&CT6&DF6&DR6 | DV6: =$B6 -> 10-L1 | DW6: =$C6 -> GTS-120 | DX6: =$D6 -> 575 | DY6: =$E6 -> 5%-7% | EA6: =DZ6*VLOOKUP(DW6,$B$157:$C$159,2,FALSE) -> 0 | ED6: =IF(DZ6="","",IF(EA6>0.049999,"",((6-ROUND(EA6*100,1))*0.01)*DX6)) | EE6: =IF(ED6="","",ED6*0.264172) | EG6: =IF(ED6="",IF(EA6=0,"",EA6),"") | EH6: =$B6 -> 10-L1 | EI6: =$C6 -> GTS-120 | EJ6: =$D6 -> 575 | EK6: =$E6 -> 5%-7% | EM6: =EL6*VLOOKUP(EI6,$B$157:$C$159,2,FALSE) -> 0 | EP6: =IF(EL6="","",IF(EM6>0.049999,"",((6-ROUND(EM6*100,1))*0.01)*EJ6)) | EQ6: =IF(EP6="","",EP6*0.264172) | ES6: =IF(EP6="",IF(EM6=0,"",EM6),"") | ET6: =$B6 -> 10-L1 | EU6: =$C6 -> GTS-120 | EV6: =$D6 -> 575 | EW6: =$E6 -> 5%-7% | EY6: =EX6*VLOOKUP(EU6,$B$157:$C$159,2,FALSE) -> 0 | FB6: =IF(EX6="","",IF(EY6>0.049999,"",((6-ROUND(EY6*100,1))*0.01)*EV6)) | FC6: =IF(FB6="","",FB6*0.264172) | FE6: =IF(FB6="",IF(EY6=0,"",EY6),"") | FF6: =$B6 -> 10-L1 | FG6: =$C6 -> GTS-120 | FH6: =$D6 -> 575 | FI6: =$E6 -> 5%-7% | FK6: =FJ6*VLOOKUP(FG6,$B$157:$C$159,2,FALSE) -> 0 | FN6: =IF(FJ6="","",IF(FK6>0.049999,"",((6-ROUND(FK6*100,1))*0.01)*FH6)) | FO6: =IF(FN6="","",FN6*0.264172) | FQ6: =IF(FN6="",IF(FK6=0,"",FK6),"") | FR6: =$B6 -> 10-L1 | FS6: =$C6 -> GTS-120 | FT6: =$D6 -> 575 | FU6: =$E6 -> 5%-7% | FW6: =FV6*VLOOKUP(FS6,$B$157:$C$159,2,FALSE) -> 0 | FZ6: =IF(FV6="","",IF(FW6>0.049999,"",((6-ROUND(FW6*100,1))*0.01)*FT6)) | GA6: =IF(FZ6="","",FZ6*0.264172) | GC6: =IF(FZ6="",IF(FW6=0,"",FW6),"") | GD6: =SUM(EE6,EQ6,FC6,FO6,GA6) -> 0 | GE6: =EF6&ER6&FD6&FP6&GB6 | GF6: =$B6 -> 10-L1 | GG6: =$C6 -> GTS-120 | GH6: =$D6 -> 575 | GI6: =$E6 -> 5%-7% | GK6: =GJ6*VLOOKUP(GG6,$B$157:$C$159,2,FALSE) -> 0 | GN6: =IF(GJ6="","",IF(GK6>0.049999,"",((6-ROUND(GK6*100,1))*0.01)*GH6)) | GO6: =IF(GN6="","",GN6*0.264172) | GQ6: =IF(GN6="",IF(GK6=0,"",GK6),"") | GR6: =$B6 -> 10-L1 | GS6: =$C6 -> GTS-120 | GT6: =$D6 -> 575 | GU6: =$E6 -> 5%-7% | GW6: =GV6*VLOOKUP(GS6,$B$157:$C$159,2,FALSE) -> 0 | GZ6: =IF(GV6="","",IF(GW6>0.049999,"",((6-ROUND(GW6*100,1))*0.01)*GT6)) | HA6: =IF(GZ6="","",GZ6*0.264172) | HC6: =IF(GZ6="",IF(GW6=0,"",GW6),"") | HD6: =$B6 -> 10-L1 | HE6: =$C6 -> GTS-120 | HF6: =$D6 -> 575 | HG6: =$E6 -> 5%-7% | HI6: =HH6*VLOOKUP(HE6,$B$157:$C$159,2,FALSE) -> 0 | HL6: =IF(HH6="","",IF(HI6>0.049999,"",((6-ROUND(HI6*100,1))*0.01)*HF6)) | HM6: =IF(HL6="","",HL6*0.264172) | HO6: =IF(HL6="",IF(HI6=0,"",HI6),"") | HP6: =$B6 -> 10-L1 | HQ6: =$C6 -> GTS-120 | HR6: =$D6 -> 575 | HS6: =$E6 -> 5%-7% | HU6: =HT6*VLOOKUP(HQ6,$B$157:$C$159,2,FALSE) -> 0 | HX6: =IF(HT6="","",IF(HU6>0.049999,"",((6-ROUND(HU6*100,1))*0.01)*HR6)) | HY6: =IF(HX6="","",HX6*0.264172) | IA6: =IF(HX6="",IF(HU6=0,"",HU6),"") | IB6: =$B6 -> 10-L1 | IC6: =$C6 -> GTS-120 | ID6: =$D6 -> 575 | IE6: =$E6 -> 5%-7% | IG6: =IF6*VLOOKUP(IC6,$B$157:$C$159,2,FALSE) -> 0 | IJ6: =IF(IF6="","",IF(IG6>0.049999,"",((6-ROUND(IG6*100,1))*0.01)*ID6)) | IK6: =IF(IJ6="","",IJ6*0.264172) | IM6: =IF(IJ6="",IF(IG6=0,"",IG6),"") | IN6: =SUM(GO6,HA6,HM6,HY6,IK6) -> 0 | IO6: =GP6&HB6&HN6&HZ6&IL6 | IP6: =$B6 -> 10-L1 | IQ6: =$C6 -> GTS-120 | IR6: =$D6 -> 575 | IS6: =$E6 -> 5%-7% | IU6: =IT6*VLOOKUP(IQ6,$B$157:$C$159,2,FALSE) -> 0 | IX6: =IF(IT6="","",IF(IU6>0.049999,"",((6-ROUND(IU6*100,1))*0.01)*IR6)) | IY6: =IF(IX6="","",IX6*0.264172) | JA6: =IF(IX6="",IF(IU6=0,"",IU6),"") | JB6: =$B6 -> 10-L1 | JC6: =$C6 -> GTS-120 | JD6: =$D6 -> 575 | JE6: =$E6 -> 5%-7% | JG6: =JF6*VLOOKUP(JC6,$B$157:$C$159,2,FALSE) -> 0 | JJ6: =IF(JF6="","",IF(JG6>0.049999,"",((6-ROUND(JG6*100,1))*0.01)*JD6)) | JK6: =IF(JJ6="","",JJ6*0.264172) | JM6: =IF(JJ6="",IF(JG6=0,"",JG6),"") | JN6: =$B6 -> 10-L1 | JO6: =$C6 -> GTS-120 | JP6: =$D6 -> 575 | JQ6: =$E6 -> 5%-7% | JS6: =JR6*VLOOKUP(JO6,$B$157:$C$159,2,FALSE) -> 0 | JV6: =IF(JR6="","",IF(JS6>0.049999,"",((6-ROUND(JS6*100,1))*0.01)*JP6)) | JW6: =IF(JV6="","",JV6*0.264172) | JY6: =IF(JV6="",IF(JS6=0,"",JS6),"") | JZ6: =$B6 -> 10-L1 | KA6: =$C6 -> GTS-120 | KB6: =$D6 -> 575 | KC6: =$E6 -> 5%-7% | KE6: =KD6*VLOOKUP(KA6,$B$157:$C$159,2,FALSE) -> 0 | KH6: =IF(KD6="","",IF(KE6>0.049999,"",((6-ROUND(KE6*100,1))*0.01)*KB6)) | KI6: =IF(KH6="","",KH6*0.264172) | KK6: =IF(KH6="",IF(KE6=0,"",KE6),"") | KL6: =$B6 -> 10-L1 | KM6: =$C6 -> GTS-120 | KN6: =$D6 -> 575 | KO6: =$E6 -> 5%-7% | KQ6: =KP6*VLOOKUP(KM6,$B$157:$C$159,2,FALSE) -> 0 | KT6: =IF(KP6="","",IF(KQ6>0.049999,"",((6-ROUND(KQ6*100,1))*0.01)*KN6)) | KU6: =IF(KT6="","",KT6*0.264172) | KW6: =IF(KT6="",IF(KQ6=0,"",KQ6),"") | KX6: =SUM(IY6,JK6,JW6,KI6,KU6) -> 0 | KY6: =IZ6&JL6&JX6&KJ6&KV6
A7: MWTH-1 | B7: 20-L1 | C7: =VLOOKUP($B7,'OP Info'!$C$4:$J$62,4,FALSE) -> GTS-120 | D7: =VLOOKUP($B7,'OP Info'!$C$4:$J$62,3,FALSE) -> 630 | E7: =CONCATENATE(VLOOKUP($B7,'OP Info'!$C$4:$J$62,5,FALSE),"%-",VLOOKUP($B7,'OP Info'!$C$4:$J$62,6,FALSE),"%") -> 5%-7% | G7: =F7*VLOOKUP(C7,$B$157:$C$159,2,FALSE) -> 0 | J7: =IF(F7="","",IF(G7>0.049999,"",((6-ROUND(G7*100,1))*0.01)*D7)) | K7: =IF(J7="","",J7*0.264172) | M7: =IF(J7="",IF(G7=0,"",G7),"") | N7: =$B7 -> 20-L1 | O7: =$C7 -> GTS-120 | P7: =$D7 -> 630 | Q7: =$E7 -> 5%-7% | S7: =R7*VLOOKUP(O7,$B$157:$C$159,2,FALSE) -> 0 | V7: =IF(R7="","",IF(S7>0.049999,"",((6-ROUND(S7*100,1))*0.01)*P7)) | W7: =IF(V7="","",V7*0.264172) | Y7: =IF(V7="",IF(S7=0,"",S7),"") | Z7: =$B7 -> 20-L1 | AA7: =$C7 -> GTS-120 | AB7: =$D7 -> 630 | AC7: =$E7 -> 5%-7% | AE7: =AD7*VLOOKUP(AA7,$B$157:$C$159,2,FALSE) -> 0 | AH7: =IF(AD7="","",IF(AE7>0.049999,"",((6-ROUND(AE7*100,1))*0.01)*AB7)) | AI7: =IF(AH7="","",AH7*0.264172) | AK7: =IF(AH7="",IF(AE7=0,"",AE7),"") | AL7: =$B7 -> 20-L1 | AM7: =$C7 -> GTS-120 | AN7: =$D7 -> 630 | AO7: =$E7 -> 5%-7% | AQ7: =AP7*VLOOKUP(AM7,$B$157:$C$159,2,FALSE) -> 0 | AT7: =IF(AP7="","",IF(AQ7>0.049999,"",((6-ROUND(AQ7*100,1))*0.01)*AN7)) | AU7: =IF(AT7="","",AT7*0.264172) | AW7: =IF(AT7="",IF(AQ7=0,"",AQ7),"") | AX7: =$B7 -> 20-L1 | AY7: =$C7 -> GTS-120 | AZ7: =$D7 -> 630 | BA7: =$E7 -> 5%-7% | BC7: =BB7*VLOOKUP(AY7,$B$157:$C$159,2,FALSE) -> 0 | BF7: =IF(BB7="","",IF(BC7>0.049999,"",((6-ROUND(BC7*100,1))*0.01)*AZ7)) | BG7: =IF(BF7="","",BF7*0.264172) | BI7: =IF(BF7="",IF(BC7=0,"",BC7),"") | BJ7: =SUM(K7,W7,AI7,AU7,BG7) -> 0 | BK7: =L7&X7&AJ7&AV7&BH7 | BL7: =$B7 -> 20-L1 | BM7: =$C7 -> GTS-120 | BN7: =$D7 -> 630 | BO7: =$E7 -> 5%-7% | BQ7: =BP7*VLOOKUP(BM7,$B$157:$C$159,2,FALSE) -> 0 | BT7: =IF(BP7="","",IF(BQ7>0.049999,"",((6-ROUND(BQ7*100,1))*0.01)*BN7)) | BU7: =IF(BT7="","",BT7*0.264172) | BW7: =IF(BT7="",IF(BQ7=0,"",BQ7),"") | BX7: =$B7 -> 20-L1 | BY7: =$C7 -> GTS-120 | BZ7: =$D7 -> 630 | CA7: =$E7 -> 5%-7% | CC7: =CB7*VLOOKUP(BY7,$B$157:$C$159,2,FALSE) -> 0 | CF7: =IF(CB7="","",IF(CC7>0.049999,"",((6-ROUND(CC7*100,1))*0.01)*BZ7)) | CG7: =IF(CF7="","",CF7*0.264172) | CI7: =IF(CF7="",IF(CC7=0,"",CC7),"") | CJ7: =$B7 -> 20-L1 | CK7: =$C7 -> GTS-120 | CL7: =$D7 -> 630 | CM7: =$E7 -> 5%-7% | CO7: =CN7*VLOOKUP(CK7,$B$157:$C$159,2,FALSE) -> 0 | CR7: =IF(CN7="","",IF(CO7>0.049999,"",((6-ROUND(CO7*100,1))*0.01)*CL7)) | CS7: =IF(CR7="","",CR7*0.264172) | CU7: =IF(CR7="",IF(CO7=0,"",CO7),"") | CV7: =$B7 -> 20-L1 | CW7: =$C7 -> GTS-120 | CX7: =$D7 -> 630 | CY7: =$E7 -> 5%-7% | DA7: =CZ7*VLOOKUP(CW7,$B$157:$C$159,2,FALSE) -> 0 | DD7: =IF(CZ7="","",IF(DA7>0.049999,"",((6-ROUND(DA7*100,1))*0.01)*CX7)) | DE7: =IF(DD7="","",DD7*0.264172) | DG7: =IF(DD7="",IF(DA7=0,"",DA7),"") | DH7: =$B7 -> 20-L1 | DI7: =$C7 -> GTS-120 | DJ7: =$D7 -> 630 | DK7: =$E7 -> 5%-7% | DM7: =DL7*VLOOKUP(DI7,$B$157:$C$159,2,FALSE) -> 0 | DP7: =IF(DL7="","",IF(DM7>0.049999,"",((6-ROUND(DM7*100,1))*0.01)*DJ7)) | DQ7: =IF(DP7="","",DP7*0.264172) | DS7: =IF(DP7="",IF(DM7=0,"",DM7),"") | DT7: =SUM(BU7,CG7,CS7,DE7,DQ7) -> 0 | DU7: =BV7&CH7&CT7&DF7&DR7 | DV7: =$B7 -> 20-L1 | DW7: =$C7 -> GTS-120 | DX7: =$D7 -> 630 | DY7: =$E7 -> 5%-7% | EA7: =DZ7*VLOOKUP(DW7,$B$157:$C$159,2,FALSE) -> 0 | ED7: =IF(DZ7="","",IF(EA7>0.049999,"",((6-ROUND(EA7*100,1))*0.01)*DX7)) | EE7: =IF(ED7="","",ED7*0.264172) | EG7: =IF(ED7="",IF(EA7=0,"",EA7),"") | EH7: =$B7 -> 20-L1 | EI7: =$C7 -> GTS-120 | EJ7: =$D7 -> 630 | EK7: =$E7 -> 5%-7% | EM7: =EL7*VLOOKUP(EI7,$B$157:$C$159,2,FALSE) -> 0 | EP7: =IF(EL7="","",IF(EM7>0.049999,"",((6-ROUND(EM7*100,1))*0.01)*EJ7)) | EQ7: =IF(EP7="","",EP7*0.264172) | ES7: =IF(EP7="",IF(EM7=0,"",EM7),"") | ET7: =$B7 -> 20-L1 | EU7: =$C7 -> GTS-120 | EV7: =$D7 -> 630 | EW7: =$E7 -> 5%-7% | EY7: =EX7*VLOOKUP(EU7,$B$157:$C$159,2,FALSE) -> 0 | FB7: =IF(EX7="","",IF(EY7>0.049999,"",((6-ROUND(EY7*100,1))*0.01)*EV7)) | FC7: =IF(FB7="","",FB7*0.264172) | FE7: =IF(FB7="",IF(EY7=0,"",EY7),"") | FF7: =$B7 -> 20-L1 | FG7: =$C7 -> GTS-120 | FH7: =$D7 -> 630 | FI7: =$E7 -> 5%-7% | FK7: =FJ7*VLOOKUP(FG7,$B$157:$C$159,2,FALSE) -> 0 | FN7: =IF(FJ7="","",IF(FK7>0.049999,"",((6-ROUND(FK7*100,1))*0.01)*FH7)) | FO7: =IF(FN7="","",FN7*0.264172) | FQ7: =IF(FN7="",IF(FK7=0,"",FK7),"") | FR7: =$B7 -> 20-L1 | FS7: =$C7 -> GTS-120 | FT7: =$D7 -> 630 | FU7: =$E7 -> 5%-7% | FW7: =FV7*VLOOKUP(FS7,$B$157:$C$159,2,FALSE) -> 0 | FZ7: =IF(FV7="","",IF(FW7>0.049999,"",((6-ROUND(FW7*100,1))*0.01)*FT7)) | GA7: =IF(FZ7="","",FZ7*0.264172) | GC7: =IF(FZ7="",IF(FW7=0,"",FW7),"") | GD7: =SUM(EE7,EQ7,FC7,FO7,GA7) -> 0 | GE7: =EF7&ER7&FD7&FP7&GB7 | GF7: =$B7 -> 20-L1 | GG7: =$C7 -> GTS-120 | GH7: =$D7 -> 630 | GI7: =$E7 -> 5%-7% | GK7: =GJ7*VLOOKUP(GG7,$B$157:$C$159,2,FALSE) -> 0 | GN7: =IF(GJ7="","",IF(GK7>0.049999,"",((6-ROUND(GK7*100,1))*0.01)*GH7)) | GO7: =IF(GN7="","",GN7*0.264172) | GQ7: =IF(GN7="",IF(GK7=0,"",GK7),"") | GR7: =$B7 -> 20-L1 | GS7: =$C7 -> GTS-120 | GT7: =$D7 -> 630 | GU7: =$E7 -> 5%-7% | GW7: =GV7*VLOOKUP(GS7,$B$157:$C$159,2,FALSE) -> 0 | GZ7: =IF(GV7="","",IF(GW7>0.049999,"",((6-ROUND(GW7*100,1))*0.01)*GT7)) | HA7: =IF(GZ7="","",GZ7*0.264172) | HC7: =IF(GZ7="",IF(GW7=0,"",GW7),"") | HD7: =$B7 -> 20-L1 | HE7: =$C7 -> GTS-120 | HF7: =$D7 -> 630 | HG7: =$E7 -> 5%-7% | HI7: =HH7*VLOOKUP(HE7,$B$157:$C$159,2,FALSE) -> 0 | HL7: =IF(HH7="","",IF(HI7>0.049999,"",((6-ROUND(HI7*100,1))*0.01)*HF7)) | HM7: =IF(HL7="","",HL7*0.264172) | HO7: =IF(HL7="",IF(HI7=0,"",HI7),"") | HP7: =$B7 -> 20-L1 | HQ7: =$C7 -> GTS-120 | HR7: =$D7 -> 630 | HS7: =$E7 -> 5%-7% | HU7: =HT7*VLOOKUP(HQ7,$B$157:$C$159,2,FALSE) -> 0 | HX7: =IF(HT7="","",IF(HU7>0.049999,"",((6-ROUND(HU7*100,1))*0.01)*HR7)) | HY7: =IF(HX7="","",HX7*0.264172) | IA7: =IF(HX7="",IF(HU7=0,"",HU7),"") | IB7: =$B7 -> 20-L1 | IC7: =$C7 -> GTS-120 | ID7: =$D7 -> 630 | IE7: =$E7 -> 5%-7% | IG7: =IF7*VLOOKUP(IC7,$B$157:$C$159,2,FALSE) -> 0 | IJ7: =IF(IF7="","",IF(IG7>0.049999,"",((6-ROUND(IG7*100,1))*0.01)*ID7)) | IK7: =IF(IJ7="","",IJ7*0.264172) | IM7: =IF(IJ7="",IF(IG7=0,"",IG7),"") | IN7: =SUM(GO7,HA7,HM7,HY7,IK7) -> 0 | IO7: =GP7&HB7&HN7&HZ7&IL7 | IP7: =$B7 -> 20-L1 | IQ7: =$C7 -> GTS-120 | IR7: =$D7 -> 630 | IS7: =$E7 -> 5%-7% | IU7: =IT7*VLOOKUP(IQ7,$B$157:$C$159,2,FALSE) -> 0 | IX7: =IF(IT7="","",IF(IU7>0.049999,"",((6-ROUND(IU7*100,1))*0.01)*IR7)) | IY7: =IF(IX7="","",IX7*0.264172) | JA7: =IF(IX7="",IF(IU7=0,"",IU7),"") | JB7: =$B7 -> 20-L1 | JC7: =$C7 -> GTS-120 | JD7: =$D7 -> 630 | JE7: =$E7 -> 5%-7% | JG7: =JF7*VLOOKUP(JC7,$B$157:$C$159,2,FALSE) -> 0 | JJ7: =IF(JF7="","",IF(JG7>0.049999,"",((6-ROUND(JG7*100,1))*0.01)*JD7)) | JK7: =IF(JJ7="","",JJ7*0.264172) | JM7: =IF(JJ7="",IF(JG7=0,"",JG7),"") | JN7: =$B7 -> 20-L1 | JO7: =$C7 -> GTS-120 | JP7: =$D7 -> 630 | JQ7: =$E7 -> 5%-7% | JS7: =JR7*VLOOKUP(JO7,$B$157:$C$159,2,FALSE) -> 0 | JV7: =IF(JR7="","",IF(JS7>0.049999,"",((6-ROUND(JS7*100,1))*0.01)*JP7)) | JW7: =IF(JV7="","",JV7*0.264172) | JY7: =IF(JV7="",IF(JS7=0,"",JS7),"") | JZ7: =$B7 -> 20-L1 | KA7: =$C7 -> GTS-120 | KB7: =$D7 -> 630 | KC7: =$E7 -> 5%-7% | KE7: =KD7*VLOOKUP(KA7,$B$157:$C$159,2,FALSE) -> 0 | KH7: =IF(KD7="","",IF(KE7>0.049999,"",((6-ROUND(KE7*100,1))*0.01)*KB7)) | KI7: =IF(KH7="","",KH7*0.264172) | KK7: =IF(KH7="",IF(KE7=0,"",KE7),"") | KL7: =$B7 -> 20-L1 | KM7: =$C7 -> GTS-120 | KN7: =$D7 -> 630 | KO7: =$E7 -> 5%-7% | KQ7: =KP7*VLOOKUP(KM7,$B$157:$C$159,2,FALSE) -> 0 | KT7: =IF(KP7="","",IF(KQ7>0.049999,"",((6-ROUND(KQ7*100,1))*0.01)*KN7)) | KU7: =IF(KT7="","",KT7*0.264172) | KW7: =IF(KT7="",IF(KQ7=0,"",KQ7),"") | KX7: =SUM(IY7,JK7,JW7,KI7,KU7) -> 0 | KY7: =IZ7&JL7&JX7&KJ7&KV7
A8: MWTH-1 | B8: 30-L1 | C8: =VLOOKUP($B8,'OP Info'!$C$4:$J$62,4,FALSE) -> GTS-120 | D8: =VLOOKUP($B8,'OP Info'!$C$4:$J$62,3,FALSE) -> 630 | E8: =CONCATENATE(VLOOKUP($B8,'OP Info'!$C$4:$J$62,5,FALSE),"%-",VLOOKUP($B8,'OP Info'!$C$4:$J$62,6,FALSE),"%") -> 5%-7% | G8: =F8*VLOOKUP(C8,$B$157:$C$159,2,FALSE) -> 0 | J8: =IF(F8="","",IF(G8>0.049999,"",((6-ROUND(G8*100,1))*0.01)*D8)) | K8: =IF(J8="","",J8*0.264172) | M8: =IF(J8="",IF(G8=0,"",G8),"") | N8: =$B8 -> 30-L1 | O8: =$C8 -> GTS-120 | P8: =$D8 -> 630 | Q8: =$E8 -> 5%-7% | S8: =R8*VLOOKUP(O8,$B$157:$C$159,2,FALSE) -> 0 | V8: =IF(R8="","",IF(S8>0.049999,"",((6-ROUND(S8*100,1))*0.01)*P8)) | W8: =IF(V8="","",V8*0.264172) | Y8: =IF(V8="",IF(S8=0,"",S8),"") | Z8: =$B8 -> 30-L1 | AA8: =$C8 -> GTS-120 | AB8: =$D8 -> 630 | AC8: =$E8 -> 5%-7% | AE8: =AD8*VLOOKUP(AA8,$B$157:$C$159,2,FALSE) -> 0 | AH8: =IF(AD8="","",IF(AE8>0.049999,"",((6-ROUND(AE8*100,1))*0.01)*AB8)) | AI8: =IF(AH8="","",AH8*0.264172) | AK8: =IF(AH8="",IF(AE8=0,"",AE8),"") | AL8: =$B8 -> 30-L1 | AM8: =$C8 -> GTS-120 | AN8: =$D8 -> 630 | AO8: =$E8 -> 5%-7% | AQ8: =AP8*VLOOKUP(AM8,$B$157:$C$159,2,FALSE) -> 0 | AT8: =IF(AP8="","",IF(AQ8>0.049999,"",((6-ROUND(AQ8*100,1))*0.01)*AN8)) | AU8: =IF(AT8="","",AT8*0.264172) | AW8: =IF(AT8="",IF(AQ8=0,"",AQ8),"") | AX8: =$B8 -> 30-L1 | AY8: =$C8 -> GTS-120 | AZ8: =$D8 -> 630 | BA8: =$E8 -> 5%-7% | BC8: =BB8*VLOOKUP(AY8,$B$157:$C$159,2,FALSE) -> 0 | BF8: =IF(BB8="","",IF(BC8>0.049999,"",((6-ROUND(BC8*100,1))*0.01)*AZ8)) | BG8: =IF(BF8="","",BF8*0.264172) | BI8: =IF(BF8="",IF(BC8=0,"",BC8),"") | BJ8: =SUM(K8,W8,AI8,AU8,BG8) -> 0 | BK8: =L8&X8&AJ8&AV8&BH8 | BL8: =$B8 -> 30-L1 | BM8: =$C8 -> GTS-120 | BN8: =$D8 -> 630 | BO8: =$E8 -> 5%-7% | BQ8: =BP8*VLOOKUP(BM8,$B$157:$C$159,2,FALSE) -> 0 | BT8: =IF(BP8="","",IF(BQ8>0.049999,"",((6-ROUND(BQ8*100,1))*0.01)*BN8)) | BU8: =IF(BT8="","",BT8*0.264172) | BW8: =IF(BT8="",IF(BQ8=0,"",BQ8),"") | BX8: =$B8 -> 30-L1 | BY8: =$C8 -> GTS-120 | BZ8: =$D8 -> 630 | CA8: =$E8 -> 5%-7% | CC8: =CB8*VLOOKUP(BY8,$B$157:$C$159,2,FALSE) -> 0 | CF8: =IF(CB8="","",IF(CC8>0.049999,"",((6-ROUND(CC8*100,1))*0.01)*BZ8)) | CG8: =IF(CF8="","",CF8*0.264172) | CI8: =IF(CF8="",IF(CC8=0,"",CC8),"") | CJ8: =$B8 -> 30-L1 | CK8: =$C8 -> GTS-120 | CL8: =$D8 -> 630 | CM8: =$E8 -> 5%-7% | CO8: =CN8*VLOOKUP(CK8,$B$157:$C$159,2,FALSE) -> 0 | CR8: =IF(CN8="","",IF(CO8>0.049999,"",((6-ROUND(CO8*100,1))*0.01)*CL8)) | CS8: =IF(CR8="","",CR8*0.264172) | CU8: =IF(CR8="",IF(CO8=0,"",CO8),"") | CV8: =$B8 -> 30-L1 | CW8: =$C8 -> GTS-120 | CX8: =$D8 -> 630 | CY8: =$E8 -> 5%-7% | DA8: =CZ8*VLOOKUP(CW8,$B$157:$C$159,2,FALSE) -> 0 | DD8: =IF(CZ8="","",IF(DA8>0.049999,"",((6-ROUND(DA8*100,1))*0.01)*CX8)) | DE8: =IF(DD8="","",DD8*0.264172) | DG8: =IF(DD8="",IF(DA8=0,"",DA8),"") | DH8: =$B8 -> 30-L1 | DI8: =$C8 -> GTS-120 | DJ8: =$D8 -> 630 | DK8: =$E8 -> 5%-7% | DM8: =DL8*VLOOKUP(DI8,$B$157:$C$159,2,FALSE) -> 0 | DP8: =IF(DL8="","",IF(DM8>0.049999,"",((6-ROUND(DM8*100,1))*0.01)*DJ8)) | DQ8: =IF(DP8="","",DP8*0.264172) | DS8: =IF(DP8="",IF(DM8=0,"",DM8),"") | DT8: =SUM(BU8,CG8,CS8,DE8,DQ8) -> 0 | DU8: =BV8&CH8&CT8&DF8&DR8 | DV8: =$B8 -> 30-L1 | DW8: =$C8 -> GTS-120 | DX8: =$D8 -> 630 | DY8: =$E8 -> 5%-7% | EA8: =DZ8*VLOOKUP(DW8,$B$157:$C$159,2,FALSE) -> 0 | ED8: =IF(DZ8="","",IF(EA8>0.049999,"",((6-ROUND(EA8*100,1))*0.01)*DX8)) | EE8: =IF(ED8="","",ED8*0.264172) | EG8: =IF(ED8="",IF(EA8=0,"",EA8),"") | EH8: =$B8 -> 30-L1 | EI8: =$C8 -> GTS-120 | EJ8: =$D8 -> 630 | EK8: =$E8 -> 5%-7% | EM8: =EL8*VLOOKUP(EI8,$B$157:$C$159,2,FALSE) -> 0 | EP8: =IF(EL8="","",IF(EM8>0.049999,"",((6-ROUND(EM8*100,1))*0.01)*EJ8)) | EQ8: =IF(EP8="","",EP8*0.264172) | ES8: =IF(EP8="",IF(EM8=0,"",EM8),"") | ET8: =$B8 -> 30-L1 | EU8: =$C8 -> GTS-120 | EV8: =$D8 -> 630 | EW8: =$E8 -> 5%-7% | EY8: =EX8*VLOOKUP(EU8,$B$157:$C$159,2,FALSE) -> 0 | FB8: =IF(EX8="","",IF(EY8>0.049999,"",((6-ROUND(EY8*100,1))*0.01)*EV8)) | FC8: =IF(FB8="","",FB8*0.264172) | FE8: =IF(FB8="",IF(EY8=0,"",EY8),"") | FF8: =$B8 -> 30-L1 | FG8: =$C8 -> GTS-120 | FH8: =$D8 -> 630 | FI8: =$E8 -> 5%-7% | FK8: =FJ8*VLOOKUP(FG8,$B$157:$C$159,2,FALSE) -> 0 | FN8: =IF(FJ8="","",IF(FK8>0.049999,"",((6-ROUND(FK8*100,1))*0.01)*FH8)) | FO8: =IF(FN8="","",FN8*0.264172) | FQ8: =IF(FN8="",IF(FK8=0,"",FK8),"") | FR8: =$B8 -> 30-L1 | FS8: =$C8 -> GTS-120 | FT8: =$D8 -> 630 | FU8: =$E8 -> 5%-7% | FW8: =FV8*VLOOKUP(FS8,$B$157:$C$159,2,FALSE) -> 0 | FZ8: =IF(FV8="","",IF(FW8>0.049999,"",((6-ROUND(FW8*100,1))*0.01)*FT8)) | GA8: =IF(FZ8="","",FZ8*0.264172) | GC8: =IF(FZ8="",IF(FW8=0,"",FW8),"") | GD8: =SUM(EE8,EQ8,FC8,FO8,GA8) -> 0 | GE8: =EF8&ER8&FD8&FP8&GB8 | GF8: =$B8 -> 30-L1 | GG8: =$C8 -> GTS-120 | GH8: =$D8 -> 630 | GI8: =$E8 -> 5%-7% | GK8: =GJ8*VLOOKUP(GG8,$B$157:$C$159,2,FALSE) -> 0 | GN8: =IF(GJ8="","",IF(GK8>0.049999,"",((6-ROUND(GK8*100,1))*0.01)*GH8)) | GO8: =IF(GN8="","",GN8*0.264172) | GQ8: =IF(GN8="",IF(GK8=0,"",GK8),"") | GR8: =$B8 -> 30-L1 | GS8: =$C8 -> GTS-120 | GT8: =$D8 -> 630 | GU8: =$E8 -> 5%-7% | GW8: =GV8*VLOOKUP(GS8,$B$157:$C$159,2,FALSE) -> 0 | GZ8: =IF(GV8="","",IF(GW8>0.049999,"",((6-ROUND(GW8*100,1))*0.01)*GT8)) | HA8: =IF(GZ8="","",GZ8*0.264172) | HC8: =IF(GZ8="",IF(GW8=0,"",GW8),"") | HD8: =$B8 -> 30-L1 | HE8: =$C8 -> GTS-120 | HF8: =$D8 -> 630 | HG8: =$E8 -> 5%-7% | HI8: =HH8*VLOOKUP(HE8,$B$157:$C$159,2,FALSE) -> 0 | HL8: =IF(HH8="","",IF(HI8>0.049999,"",((6-ROUND(HI8*100,1))*0.01)*HF8)) | HM8: =IF(HL8="","",HL8*0.264172) | HO8: =IF(HL8="",IF(HI8=0,"",HI8),"") | HP8: =$B8 -> 30-L1 | HQ8: =$C8 -> GTS-120 | HR8: =$D8 -> 630 | HS8: =$E8 -> 5%-7% | HU8: =HT8*VLOOKUP(HQ8,$B$157:$C$159,2,FALSE) -> 0 | HX8: =IF(HT8="","",IF(HU8>0.049999,"",((6-ROUND(HU8*100,1))*0.01)*HR8)) | HY8: =IF(HX8="","",HX8*0.264172) | IA8: =IF(HX8="",IF(HU8=0,"",HU8),"") | IB8: =$B8 -> 30-L1 | IC8: =$C8 -> GTS-120 | ID8: =$D8 -> 630 | IE8: =$E8 -> 5%-7% | IG8: =IF8*VLOOKUP(IC8,$B$157:$C$159,2,FALSE) -> 0 | IJ8: =IF(IF8="","",IF(IG8>0.049999,"",((6-ROUND(IG8*100,1))*0.01)*ID8)) | IK8: =IF(IJ8="","",IJ8*0.264172) | IM8: =IF(IJ8="",IF(IG8=0,"",IG8),"") | IN8: =SUM(GO8,HA8,HM8,HY8,IK8) -> 0 | IO8: =GP8&HB8&HN8&HZ8&IL8 | IP8: =$B8 -> 30-L1 | IQ8: =$C8 -> GTS-120 | IR8: =$D8 -> 630 | IS8: =$E8 -> 5%-7% | IU8: =IT8*VLOOKUP(IQ8,$B$157:$C$159,2,FALSE) -> 0 | IX8: =IF(IT8="","",IF(IU8>0.049999,"",((6-ROUND(IU8*100,1))*0.01)*IR8)) | IY8: =IF(IX8="","",IX8*0.264172) | JA8: =IF(IX8="",IF(IU8=0,"",IU8),"") | JB8: =$B8 -> 30-L1 | JC8: =$C8 -> GTS-120 | JD8: =$D8 -> 630 | JE8: =$E8 -> 5%-7% | JG8: =JF8*VLOOKUP(JC8,$B$157:$C$159,2,FALSE) -> 0 | JJ8: =IF(JF8="","",IF(JG8>0.049999,"",((6-ROUND(JG8*100,1))*0.01)*JD8)) | JK8: =IF(JJ8="","",JJ8*0.264172) | JM8: =IF(JJ8="",IF(JG8=0,"",JG8),"") | JN8: =$B8 -> 30-L1 | JO8: =$C8 -> GTS-120 | JP8: =$D8 -> 630 | JQ8: =$E8 -> 5%-7% | JS8: =JR8*VLOOKUP(JO8,$B$157:$C$159,2,FALSE) -> 0 | JV8: =IF(JR8="","",IF(JS8>0.049999,"",((6-ROUND(JS8*100,1))*0.01)*JP8)) | JW8: =IF(JV8="","",JV8*0.264172) | JY8: =IF(JV8="",IF(JS8=0,"",JS8),"") | JZ8: =$B8 -> 30-L1 | KA8: =$C8 -> GTS-120 | KB8: =$D8 -> 630 | KC8: =$E8 -> 5%-7% | KE8: =KD8*VLOOKUP(KA8,$B$157:$C$159,2,FALSE) -> 0 | KH8: =IF(KD8="","",IF(KE8>0.049999,"",((6-ROUND(KE8*100,1))*0.01)*KB8)) | KI8: =IF(KH8="","",KH8*0.264172) | KK8: =IF(KH8="",IF(KE8=0,"",KE8),"") | KL8: =$B8 -> 30-L1 | KM8: =$C8 -> GTS-120 | KN8: =$D8 -> 630 | KO8: =$E8 -> 5%-7% | KQ8: =KP8*VLOOKUP(KM8,$B$157:$C$159,2,FALSE) -> 0 | KT8: =IF(KP8="","",IF(KQ8>0.049999,"",((6-ROUND(KQ8*100,1))*0.01)*KN8)) | KU8: =IF(KT8="","",KT8*0.264172) | KW8: =IF(KT8="",IF(KQ8=0,"",KQ8),"") | KX8: =SUM(IY8,JK8,JW8,KI8,KU8) -> 0 | KY8: =IZ8&JL8&JX8&KJ8&KV8
A9: MWTH-1 | B9: 50 A/B-L1 | C9: =VLOOKUP($B9,'OP Info'!$C$4:$J$62,4,FALSE) -> AQ-YB | D9: =VLOOKUP($B9,'OP Info'!$C$4:$J$62,3,FALSE) -> 3300 | E9: =CONCATENATE(VLOOKUP($B9,'OP Info'!$C$4:$J$62,5,FALSE),"%-",VLOOKUP($B9,'OP Info'!$C$4:$J$62,6,FALSE),"%") -> 5%-7% | G9: =F9*VLOOKUP(C9,$B$157:$C$159,2,FALSE) -> 0 | J9: =IF(F9="","",IF(G9>0.049999,"",((6-ROUND(G9*100,1))*0.01)*D9)) | K9: =IF(J9="","",J9*0.264172) | M9: =IF(J9="",IF(G9=0,"",G9),"") | N9: =$B9 -> 50 A/B-L1 | O9: =$C9 -> AQ-YB | P9: =$D9 -> 3300 | Q9: =$E9 -> 5%-7% | S9: =R9*VLOOKUP(O9,$B$157:$C$159,2,FALSE) -> 0 | V9: =IF(R9="","",IF(S9>0.049999,"",((6-ROUND(S9*100,1))*0.01)*P9)) | W9: =IF(V9="","",V9*0.264172) | Y9: =IF(V9="",IF(S9=0,"",S9),"") | Z9: =$B9 -> 50 A/B-L1 | AA9: =$C9 -> AQ-YB | AB9: =$D9 -> 3300 | AC9: =$E9 -> 5%-7% | AE9: =AD9*VLOOKUP(AA9,$B$157:$C$159,2,FALSE) -> 0 | AH9: =IF(AD9="","",IF(AE9>0.049999,"",((6-ROUND(AE9*100,1))*0.01)*AB9)) | AI9: =IF(AH9="","",AH9*0.264172) | AK9: =IF(AH9="",IF(AE9=0,"",AE9),"") | AL9: =$B9 -> 50 A/B-L1 | AM9: =$C9 -> AQ-YB | AN9: =$D9 -> 3300 | AO9: =$E9 -> 5%-7% | AQ9: =AP9*VLOOKUP(AM9,$B$157:$C$159,2,FALSE) -> 0 | AT9: =IF(AP9="","",IF(AQ9>0.049999,"",((6-ROUND(AQ9*100,1))*0.01)*AN9)) | AU9: =IF(AT9="","",AT9*0.264172) | AW9: =IF(AT9="",IF(AQ9=0,"",AQ9),"") | AX9: =$B9 -> 50 A/B-L1 | AY9: =$C9 -> AQ-YB | AZ9: =$D9 -> 3300 | BA9: =$E9 -> 5%-7% | BC9: =BB9*VLOOKUP(AY9,$B$157:$C$159,2,FALSE) -> 0 | BF9: =IF(BB9="","",IF(BC9>0.049999,"",((6-ROUND(BC9*100,1))*0.01)*AZ9)) | BG9: =IF(BF9="","",BF9*0.264172) | BI9: =IF(BF9="",IF(BC9=0,"",BC9),"") | BJ9: =SUM(K9,W9,AI9,AU9,BG9) -> 0 | BK9: =L9&X9&AJ9&AV9&BH9 | BL9: =$B9 -> 50 A/B-L1 | BM9: =$C9 -> AQ-YB | BN9: =$D9 -> 3300 | BO9: =$E9 -> 5%-7% | BQ9: =BP9*VLOOKUP(BM9,$B$157:$C$159,2,FALSE) -> 0 | BT9: =IF(BP9="","",IF(BQ9>0.049999,"",((6-ROUND(BQ9*100,1))*0.01)*BN9)) | BU9: =IF(BT9="","",BT9*0.264172) | BW9: =IF(BT9="",IF(BQ9=0,"",BQ9),"") | BX9: =$B9 -> 50 A/B-L1 | BY9: =$C9 -> AQ-YB | BZ9: =$D9 -> 3300 | CA9: =$E9 -> 5%-7% | CC9: =CB9*VLOOKUP(BY9,$B$157:$C$159,2,FALSE) -> 0 | CF9: =IF(CB9="","",IF(CC9>0.049999,"",((6-ROUND(CC9*100,1))*0.01)*BZ9)) | CG9: =IF(CF9="","",CF9*0.264172) | CI9: =IF(CF9="",IF(CC9=0,"",CC9),"") | CJ9: =$B9 -> 50 A/B-L1 | CK9: =$C9 -> AQ-YB | CL9: =$D9 -> 3300 | CM9: =$E9 -> 5%-7% | CO9: =CN9*VLOOKUP(CK9,$B$157:$C$159,2,FALSE) -> 0 | CR9: =IF(CN9="","",IF(CO9>0.049999,"",((6-ROUND(CO9*100,1))*0.01)*CL9)) | CS9: =IF(CR9="","",CR9*0.264172) | CU9: =IF(CR9="",IF(CO9=0,"",CO9),"") | CV9: =$B9 -> 50 A/B-L1 | CW9: =$C9 -> AQ-YB | CX9: =$D9 -> 3300 | CY9: =$E9 -> 5%-7% | DA9: =CZ9*VLOOKUP(CW9,$B$157:$C$159,2,FALSE) -> 0 | DD9: =IF(CZ9="","",IF(DA9>0.049999,"",((6-ROUND(DA9*100,1))*0.01)*CX9)) | DE9: =IF(DD9="","",DD9*0.264172) | DG9: =IF(DD9="",IF(DA9=0,"",DA9),"") | DH9: =$B9 -> 50 A/B-L1 | DI9: =$C9 -> AQ-YB | DJ9: =$D9 -> 3300 | DK9: =$E9 -> 5%-7% | DM9: =DL9*VLOOKUP(DI9,$B$157:$C$159,2,FALSE) -> 0 | DP9: =IF(DL9="","",IF(DM9>0.049999,"",((6-ROUND(DM9*100,1))*0.01)*DJ9)) | DQ9: =IF(DP9="","",DP9*0.264172) | DS9: =IF(DP9="",IF(DM9=0,"",DM9),"") | DT9: =SUM(BU9,CG9,CS9,DE9,DQ9) -> 0 | DU9: =BV9&CH9&CT9&DF9&DR9 | DV9: =$B9 -> 50 A/B-L1 | DW9: =$C9 -> AQ-YB | DX9: =$D9 -> 3300 | DY9: =$E9 -> 5%-7% | EA9: =DZ9*VLOOKUP(DW9,$B$157:$C$159,2,FALSE) -> 0 | ED9: =IF(DZ9="","",IF(EA9>0.049999,"",((6-ROUND(EA9*100,1))*0.01)*DX9)) | EE9: =IF(ED9="","",ED9*0.264172) | EG9: =IF(ED9="",IF(EA9=0,"",EA9),"") | EH9: =$B9 -> 50 A/B-L1 | EI9: =$C9 -> AQ-YB | EJ9: =$D9 -> 3300 | EK9: =$E9 -> 5%-7% | EM9: =EL9*VLOOKUP(EI9,$B$157:$C$159,2,FALSE) -> 0 | EP9: =IF(EL9="","",IF(EM9>0.049999,"",((6-ROUND(EM9*100,1))*0.01)*EJ9)) | EQ9: =IF(EP9="","",EP9*0.264172) | ES9: =IF(EP9="",IF(EM9=0,"",EM9),"") | ET9: =$B9 -> 50 A/B-L1 | EU9: =$C9 -> AQ-YB | EV9: =$D9 -> 3300 | EW9: =$E9 -> 5%-7% | EY9: =EX9*VLOOKUP(EU9,$B$157:$C$159,2,FALSE) -> 0 | FB9: =IF(EX9="","",IF(EY9>0.049999,"",((6-ROUND(EY9*100,1))*0.01)*EV9)) | FC9: =IF(FB9="","",FB9*0.264172) | FE9: =IF(FB9="",IF(EY9=0,"",EY9),"") | FF9: =$B9 -> 50 A/B-L1 | FG9: =$C9 -> AQ-YB | FH9: =$D9 -> 3300 | FI9: =$E9 -> 5%-7% | FK9: =FJ9*VLOOKUP(FG9,$B$157:$C$159,2,FALSE) -> 0 | FN9: =IF(FJ9="","",IF(FK9>0.049999,"",((6-ROUND(FK9*100,1))*0.01)*FH9)) | FO9: =IF(FN9="","",FN9*0.264172) | FQ9: =IF(FN9="",IF(FK9=0,"",FK9),"") | FR9: =$B9 -> 50 A/B-L1 | FS9: =$C9 -> AQ-YB | FT9: =$D9 -> 3300 | FU9: =$E9 -> 5%-7% | FW9: =FV9*VLOOKUP(FS9,$B$157:$C$159,2,FALSE) -> 0 | FZ9: =IF(FV9="","",IF(FW9>0.049999,"",((6-ROUND(FW9*100,1))*0.01)*FT9)) | GA9: =IF(FZ9="","",FZ9*0.264172) | GC9: =IF(FZ9="",IF(FW9=0,"",FW9),"") | GD9: =SUM(EE9,EQ9,FC9,FO9,GA9) -> 0 | GE9: =EF9&ER9&FD9&FP9&GB9 | GF9: =$B9 -> 50 A/B-L1 | GG9: =$C9 -> AQ-YB | GH9: =$D9 -> 3300 | GI9: =$E9 -> 5%-7% | GK9: =GJ9*VLOOKUP(GG9,$B$157:$C$159,2,FALSE) -> 0 | GN9: =IF(GJ9="","",IF(GK9>0.049999,"",((6-ROUND(GK9*100,1))*0.01)*GH9)) | GO9: =IF(GN9="","",GN9*0.264172) | GQ9: =IF(GN9="",IF(GK9=0,"",GK9),"") | GR9: =$B9 -> 50 A/B-L1 | GS9: =$C9 -> AQ-YB | GT9: =$D9 -> 3300 | GU9: =$E9 -> 5%-7% | GW9: =GV9*VLOOKUP(GS9,$B$157:$C$159,2,FALSE) -> 0 | GZ9: =IF(GV9="","",IF(GW9>0.049999,"",((6-ROUND(GW9*100,1))*0.01)*GT9)) | HA9: =IF(GZ9="","",GZ9*0.264172) | HC9: =IF(GZ9="",IF(GW9=0,"",GW9),"") | HD9: =$B9 -> 50 A/B-L1 | HE9: =$C9 -> AQ-YB | HF9: =$D9 -> 3300 | HG9: =$E9 -> 5%-7% | HI9: =HH9*VLOOKUP(HE9,$B$157:$C$159,2,FALSE) -> 0 | HL9: =IF(HH9="","",IF(HI9>0.049999,"",((6-ROUND(HI9*100,1))*0.01)*HF9)) | HM9: =IF(HL9="","",HL9*0.264172) | HO9: =IF(HL9="",IF(HI9=0,"",HI9),"") | HP9: =$B9 -> 50 A/B-L1 | HQ9: =$C9 -> AQ-YB | HR9: =$D9 -> 3300 | HS9: =$E9 -> 5%-7% | HU9: =HT9*VLOOKUP(HQ9,$B$157:$C$159,2,FALSE) -> 0 | HX9: =IF(HT9="","",IF(HU9>0.049999,"",((6-ROUND(HU9*100,1))*0.01)*HR9)) | HY9: =IF(HX9="","",HX9*0.264172) | IA9: =IF(HX9="",IF(HU9=0,"",HU9),"") | IB9: =$B9 -> 50 A/B-L1 | IC9: =$C9 -> AQ-YB | ID9: =$D9 -> 3300 | IE9: =$E9 -> 5%-7% | IG9: =IF9*VLOOKUP(IC9,$B$157:$C$159,2,FALSE) -> 0 | IJ9: =IF(IF9="","",IF(IG9>0.049999,"",((6-ROUND(IG9*100,1))*0.01)*ID9)) | IK9: =IF(IJ9="","",IJ9*0.264172) | IM9: =IF(IJ9="",IF(IG9=0,"",IG9),"") | IN9: =SUM(GO9,HA9,HM9,HY9,IK9) -> 0 | IO9: =GP9&HB9&HN9&HZ9&IL9 | IP9: =$B9 -> 50 A/B-L1 | IQ9: =$C9 -> AQ-YB | IR9: =$D9 -> 3300 | IS9: =$E9 -> 5%-7% | IU9: =IT9*VLOOKUP(IQ9,$B$157:$C$159,2,FALSE) -> 0 | IX9: =IF(IT9="","",IF(IU9>0.049999,"",((6-ROUND(IU9*100,1))*0.01)*IR9)) | IY9: =IF(IX9="","",IX9*0.264172) | JA9: =IF(IX9="",IF(IU9=0,"",IU9),"") | JB9: =$B9 -> 50 A/B-L1 | JC9: =$C9 -> AQ-YB | JD9: =$D9 -> 3300 | JE9: =$E9 -> 5%-7% | JG9: =JF9*VLOOKUP(JC9,$B$157:$C$159,2,FALSE) -> 0 | JJ9: =IF(JF9="","",IF(JG9>0.049999,"",((6-ROUND(JG9*100,1))*0.01)*JD9)) | JK9: =IF(JJ9="","",JJ9*0.264172) | JM9: =IF(JJ9="",IF(JG9=0,"",JG9),"") | JN9: =$B9 -> 50 A/B-L1 | JO9: =$C9 -> AQ-YB | JP9: =$D9 -> 3300 | JQ9: =$E9 -> 5%-7% | JS9: =JR9*VLOOKUP(JO9,$B$157:$C$159,2,FALSE) -> 0 | JV9: =IF(JR9="","",IF(JS9>0.049999,"",((6-ROUND(JS9*100,1))*0.01)*JP9)) | JW9: =IF(JV9="","",JV9*0.264172) | JY9: =IF(JV9="",IF(JS9=0,"",JS9),"") | JZ9: =$B9 -> 50 A/B-L1 | KA9: =$C9 -> AQ-YB | KB9: =$D9 -> 3300 | KC9: =$E9 -> 5%-7% | KE9: =KD9*VLOOKUP(KA9,$B$157:$C$159,2,FALSE) -> 0 | KH9: =IF(KD9="","",IF(KE9>0.049999,"",((6-ROUND(KE9*100,1))*0.01)*KB9)) | KI9: =IF(KH9="","",KH9*0.264172) | KK9: =IF(KH9="",IF(KE9=0,"",KE9),"") | KL9: =$B9 -> 50 A/B-L1 | KM9: =$C9 -> AQ-YB | KN9: =$D9 -> 3300 | KO9: =$E9 -> 5%-7% | KQ9: =KP9*VLOOKUP(KM9,$B$157:$C$159,2,FALSE) -> 0 | KT9: =IF(KP9="","",IF(KQ9>0.049999,"",((6-ROUND(KQ9*100,1))*0.01)*KN9)) | KU9: =IF(KT9="","",KT9*0.264172) | KW9: =IF(KT9="",IF(KQ9=0,"",KQ9),"") | KX9: =SUM(IY9,JK9,JW9,KI9,KU9) -> 0 | KY9: =IZ9&JL9&JX9&KJ9&KV9
